Workbook

Sheet Calculation Sheet
B1: TPS2592xx Design Calculation Tool
B2: Constants Cells | C2: Input/SelectCells | D2: Calculation Cells | G2: Recommended Value
C3: Calculated, but can be over-ridden by user
B4: Parameter | C4: Description | D4: Value | E4: Units | F4: Tolerance | T4: Version | U4: VOVC (V) | V4: Max Rdson (mΩ) @ 25 degC | W4: Max Rdson (mΩ) @ 125 degC
B5: 12V or 5V version | C5: Select among TPS25923x/4x/5x/6x for Over Voltage Clamp | D5: TPS25923 | G5: =IF(OR(D5= "TPS25923",D5= "TPS25925"),6.1,IF(OR(D5 = "TPS25924",D5= "TPS25926"),15,18)) -> 6.1 | T5: TPS25923 | U5: 6.1 | V5: 37 | W5: 48
B6: VIN (max) | C6: Maximum system input voltage (magnitude) | D6: 5 | E6: V | F6: % | T6: TPS25924 | U6: 15 | V6: 37 | W6: 48
B7: UVset | C7: Power Failure Detection Threshold (VIN Falling) | D7: 4 | E7: V | T7: TPS25925 | U7: 6.1 | V7: 39 | W7: 50
B8: Cout | C8: Load Capacitance | D8: 10 | E8: uF | F8: 0.1 | T8: TPS25926 | U8: 15 | V8: 39 | W8: 50
B9: Rlstart | C9: Load at start-up (assumed to be resistive) | D9: 4 | E9: Ohm | G9: =1.1*Vcc_max/Ilimit -> 5.7291667 | T9: TPS25927 | U9: No Clamp | V9: 37 | W9: 48
B10: Imax | C10: Maximum continuous load current (magnitude) | D10: 0.8 | E10: A
B11: Ilimit | C11: Current Limit, 20% higher than maximum continuous load current | D11: =1.2*Imax -> 0.96 | E11: A
B13: UVLO set point calculations
B14: R1: Pullup at UVLO Pin | C14: Select a value > 100K to keep I_R12 low | D14: 1000 | E14: kOhm | F14: 0.01 | M14: =IF(D14>=100,D14,IF(D14>=10,D14*10,D14*100)) -> 1000
B15: R2_cal | C15: Calculated value of Resistor at UVLO pin | D15: =RpUVLO/(UVset/UVref -1) -> 509.43396 | E15: kOhm | J15: =D18 -> 3.9918787 | K15: Power Fail (VIN Falling) | M15: =IF(D15>=100,D15,IF(D15>=10,D15*10,D15*100)) -> 509.43396
B16: SELECT THE VALUE OF RESISTORS AS CLOSEST AVAILABLE VALUE OF R2 | J16: =D19 -> 4.139726 | K16: Release UVLO (VIN Rising)
B17: R2 | C17: Select the closest possible value as R2_cal | D17: =G17 -> 511 | E17: kOhm | F17: =F14 -> 0.01 | G17: =M17*D15/M15 -> 511 | J17: =IF(D21="No Clamp",, D21) -> 6.1 | K17: OV Clamp (VIN Rising) | M17: =INDEX('Res EIA Tables'!E$5:E$197,2+MATCH(M15,'Res EIA Tables'!E$5:E$197)) -> 511
B18: UV_final | C18: =C7 -> Power Failure Detection Threshold (VIN Falling) | D18: =UVref*(1+RpUVLO/D17) -> 3.9918787 | E18: V | F18: =SQRT(F75^2+F14^2+F17^2) -> 0.033166248
B19: EN_final | C19: Release UVLO, Enable Chip (VIN Rising) | D19: =(UVref+0.05)*(1+RpUVLO/D17) -> 4.139726 | E19: V | F19: =F18 -> 0.033166248
B20: I_R12 | C20: Current in R1, R2 Branch | D20: =Vcc_max*1000/(RpUVLO+D17) -> 3.3090668 | E20: uA
B21: VOVC | C21: Over Voltage Clamp | D21: =INDEX(U5:U9,MATCH(D5,T5:T9)) -> 6.1 | E21: V | F21: 0.1
B23: Calculations for Ilimit (resistor on Ilimit Pin)
B24: RLIM_cal | C24: Calculated current limit resistor | D24: =(Ilimit-0.7)/(0.03) -> 8.6666667 | E24: kOhm | J24: =Icharge -> 0.15242857 | K24: Inrush Charging Current | M24: =IF(D24>=100,D24,IF(D24>=10,D24*10,D24*100)) -> 866.66667
B25: SELECT A ILIMIT RESISTOR WITH THE CLOSEST AVAILABLE VALUE OF Rilim_Cal | J25: =Ilimit_final -> 0.9661 | K25: Overload Curr Limit
B26: RLIM | C26: Select the closest available value of RLIM_cal | D26: =G26 -> 8.87 | E26: kOhm | F26: 0.01 | G26: =M26*D24/M24 -> 8.87 | J26: =D28 -> 1.54576 | K26: Fastrip Curr Limit | M26: =INDEX('Res EIA Tables'!E$5:E$197,2+MATCH(M24,'Res EIA Tables'!E$5:E$197)) -> 887
B27: Ilimit_final | C27: Final current Limit Set Point | D27: =(0.7+0.03*Rilim) -> 0.9661 | E27: A | F27: =SQRT(0.08^2+F26^2) -> 0.080622577
B28: Ifstrip | C28: Fast-Trip Current Limit to detect short circuit | D28: =1.6*Ilimit_final -> 1.54576 | E28: A | F28: =SQRT(F27^2+0.2^2) -> 0.21563859
B31: Calculations for SoftStart control (external cap on dVdT pin)
B32: Parameter | C32: Description | D32: Value | E32: Units | F32: Tolerance
B33: I_dVdT | C33: Internal current charging capacitor on dVdT | D33: 0.22 | E33: uA | F33: 0.15
B34: Gain_dVdT | C34: Internal Gain for dVdT Control | D34: 4.85 | E34: V/V | F34: 0.03
B35: Icharge_fastest | C35: Charging current when charging at fastest possible rate If this current is < Ilimit, no capacitor is required at dVdT pin | D35: =MIN(Cout*Gain_dvdt*I_dvdt/70, Ilimit_final) -> 0.15242857 | E35: A
B36: Tchg_fastest | C36: No capacitor on dVdT pin, No Load at start-up | D36: =Vcc_max*Cout*0.001/D35 -> 0.32802249 | E36: ms | F36: 0.2
B37: Tchg_req | C37: The charging time required | D37: 1 | E37: ms
B38: Icharge_req | C38: Charging (inrush) current desired in the system | D38: 0.5 | E38: A
B39: Cext_dvdt_cal1 | C39: calculated value of capacitor at dVdT pin for required Tcharge | D39: =IF(Tchg_req<D36, 0, (I_dvdt*Gain_dvdt*Tchg_req/Vcc_max)) -> 0.2134 | E39: nF
B40: Cext_dvdt_cal2 | C40: calculated value of capacitor at dVdT pin for required Icharge | D40: =(I_dvdt*Gain_dvdt*Cout*0.001/Icharge_req) -> 0.02134 | E40: nF | G40: =MAX(Cdvdt_ext_cal1,Cext_dvdt_cal2) -> 0.2134
B41: SELECT A CAPACITOR WITH THE CLOSEST POSSIBLE VALUE to max(Cext_dvdt_cal1, Cext_dvdt_cal2)
B42: CdVdT_ext | C42: The external capacitor connecetd across dVdT pin | D42: 0 | E42: nF | F42: 0.1 | G42: =IF(G40>1, INDEX('Cap Tables'!B4:B75,1+MATCH(G40,'Cap Tables'!B4:B75)), INDEX('Cap Tables'!A4:A75,1+MATCH(G40*10,'Cap Tables'!A4:A75))/10) -> 0.22
B43: Icharge | C43: Charging Current as per dVdT setting | D43: =Cout*0.000001*Gain_dvdt*I_dvdt*0.000001/(Cdvdt_ext*0.000000001+0.00000000007) -> 0.15242857 | E43: A | F43: =SQRT(F45^2+F8^2) -> 0.20832667
B44: Does Device Enter Current Limit during start-up? | D44: =((Icharge+Vcc_max/Rlstart) >= Ilimit_final) -> 1 | G44: =Cout*0.001*Rlstart*(Ilimit_final/Icharge -1+LN(Icharge/(Ilimit_final-Vcc_max/Rlstart))) -> #VALUE!
...

Sheet Thermal Shutdown Limit Plot
A1: Thermal Shutdown Time Vs. Power Dissipation | H1: Title of Graph | J1: Thermal Shutdown Time Vs. Power Dissipation
A2: Power Dissipation | B2: TA = -40 C | C2: TA = 25 C | D2: TA = 85 C | E2: TA = 125 C
A3: 0.6 | E3: 11724 | F3: A
A4: 0.71 | E4: 2292 | F4: A
A5: 0.78 | E5: 1419 | F5: A
A6: 1.5 | E6: 118 | F6: A
A7: 2.06 | D7: 12185 | E7: 50 | F7: E | H7: Lable | I7: X-Axis | J7: Power Dissipation (W)
A8: 2.14 | D8: 10225 | E8: 42 | F8: E
A9: 2.25 | D9: 4228 | E9: 37 | F9: A
A10: 2.41 | D10: 3248 | E10: 30 | F10: E
A11: 2.57 | D11: 2011 | E11: 25 | F11: E
A12: 2.74 | D12: 1226 | E12: 20 | F12: E
A13: 2.87 | D13: 829 | E13: 16 | F13: E
A14: 3.03 | D14: 516 | E14: 13 | F14: E
A15: 3.2 | C15: 13698 | D15: 459 | E15: 12 | F15: E
A16: 3.33 | C16: 9564 | D16: 428 | E16: 10 | F16: A
A17: 5 | C17: 1096 | D17: 91 | E17: 3.1 | F17: A
A18: 7.3 | C18: 208 | D18: 22 | E18: 1.4 | F18: A
A19: 7.8 | B19: 9357 | C19: 160 | D19: 18 | E19: 1.2 | F19: E
A20: 10 | B20: 867 | C20: 76.5 | D20: 9.85 | E20: 0.88 | F20: A
A21: 15 | B21: 101 | C21: 19.44 | D21: 3.03 | E21: 0.5 | F21: A
A22: 20 | B22: 32.7 | C22: 9.33 | D22: 1.72 | E22: 0.33 | F22: A
A23: 25 | B23: 17.18 | C23: 4.47 | D23: 1.19 | E23: 0.255 | F23: A
A24: 30 | B24: 10.86 | C24: 2.73 | D24: 0.88 | E24: 0.197 | F24: A
A25: 35 | B25: 5.96 | C25: 2 | D25: 0.7 | E25: 0.173 | F25: A
A26: 40 | B26: 4.6315 | C26: 1.78 | D26: 0.611 | E26: 0.164 | F26: A
A27: 45 | B27: 3.18 | C27: 1.36 | D27: 0.485 | E27: 0.147 | F27: A
A28: 52 | B28: 2.26 | C28: 1 | D28: 0.4 | E28: 0.11 | F28: A
D30: E: Estimated
D31: A: Actual Measured
B33: Pd | C33: Tstart
B34: ='Calculation Sheet'!D50 -> 1.4227381 | C34: =Tchg_dvdt -> #VALUE!

Sheet Res EIA Tables
A1: Standard EIA Decade Resistor Values
A3: 0.2 | B3: 0.1 | C3: 0.05 | D3: 0.02 | E3: 0.01 | F3: 0.5%, 0.25%, 0.1%
A4: E6 | B4: E12 | C4: E24 | D4: E48 | E4: E96 | F4: E192
A5: 100 | B5: 100 | C5: 100 | D5: 100 | E5: 100 | F5: 100
F6: 101
E7: 102 | F7: 102
F8: 104
D9: 105 | E9: 105 | F9: 105
F10: 106
E11: 107 | F11: 107
F12: 109
C13: 110 | D13: 110 | E13: 110 | F13: 110
F14: 111
E15: 113 | F15: 113
F16: 114
D17: 115 | E17: 115 | F17: 115
F18: 117
E19: 118 | F19: 118
F20: 120
B21: 120 | C21: 120 | D21: 121 | E21: 121 | F21: 121
F22: 123
E23: 124 | F23: 124
F24: 126
D25: 127 | E25: 127 | F25: 127
F26: 129
E27: 130 | F27: 130
F28: 132
C29: 130 | D29: 133 | E29: 133 | F29: 133
F30: 135
E31: 137 | F31: 137
F32: 138
D33: 140 | E33: 140 | F33: 140
F34: 142
E35: 143 | F35: 143
F36: 145
A37: 150 | B37: 150 | C37: 150 | D37: 147 | E37: 147 | F37: 147
F38: 149
E39: 150 | F39: 150
F40: 152
D41: 154 | E41: 154 | F41: 154
...

Sheet Cap Tables
A1: Standard Capacitor Values
A3: pF | B3: nF | C3: µF | D3: mF
A4: 1 | B4: 1 | C4: 1 | D4: 1
A5: 1.1 | B5: 1.1
A6: 1.2 | B6: 1.2
A7: 1.3 | B7: 1.3
A8: 1.5 | B8: 1.5 | C8: 1.5 | D8: 1.5
A9: 1.6 | B9: 1.6
A10: 1.8 | B10: 1.8
A11: 2 | B11: 2
A12: 2.2 | B12: 2.2 | C12: 2.2 | D12: 2.2
A13: 2.4 | B13: 2.4
A14: 2.7 | B14: 2.7
A15: 3 | B15: 3
A16: 3.3 | B16: 3.3 | C16: 3.3 | D16: 3.3
A17: 3.6 | B17: 3.6 | C17: =C18 -> 4.7
A18: 3.9 | B18: 3.9 | C18: =C19 -> 4.7
A19: 4.3 | B19: 4.3 | C19: =C20 -> 4.7
A20: 4.7 | B20: 4.7 | C20: 4.7 | D20: 4.7
A21: 5.1 | B21: 5.1 | C21: =C22 -> 6.8
A22: 5.6 | B22: 5.6 | C22: =C23 -> 6.8
A23: 6.2 | B23: 6.2 | C23: =C24 -> 6.8
A24: 6.8 | B24: 6.8 | C24: 6.8 | D24: 6.8
A25: 7.5 | B25: 7.5 | C25: =C26 -> 10
A26: 8.2 | B26: 8.2 | C26: =C27 -> 10
A27: 9.1 | B27: 9.1 | C27: =C28 -> 10
A28: 10 | B28: 10 | C28: 10 | D28: 10
A29: 11 | B29: =B30 -> 15 | C29: =C30 -> 15
A30: 12 | B30: =B31 -> 15 | C30: =C31 -> 15
A31: 13 | B31: =B32 -> 15 | C31: =C32 -> 15
A32: 15 | B32: 15 | C32: 15
A33: 16 | B33: =B34 -> 22 | C33: =C34 -> 22
A34: 18 | B34: =B35 -> 22 | C34: =C35 -> 22
A35: 20 | B35: =B36 -> 22 | C35: =C36 -> 22
A36: 22 | B36: 22 | C36: 22
A37: 24 | B37: =B38 -> 33 | C37: =C38 -> 33
A38: 27 | B38: =B39 -> 33 | C38: =C39 -> 33
A39: 30 | B39: =B40 -> 33 | C39: =C40 -> 33
A40: 33 | B40: 33 | C40: 33
A41: 36 | B41: =B42 -> 47 | C41: =C42 -> 47
...
